Traceback (most recent call last):
  File "/usr/lib/python3/dist-packages/urllib3/response.py", line 425, in _error_catcher
    yield
  File "/usr/lib/python3/dist-packages/urllib3/response.py", line 507, in read
    data = self._fp.read(amt) if not fp_closed else b""
  File "/usr/lib/python3.8/http/client.py", line 459, in read
    n = self.readinto(b)
  File "/usr/lib/python3.8/http/client.py", line 503, in readinto
    n = self.fp.readinto(b)
  File "/usr/lib/python3.8/socket.py", line 669, in readinto
    return self._sock.recv_into(b)
  File "/usr/lib/python3.8/ssl.py", line 1241, in recv_into
    return self.read(nbytes, buffer)
  File "/usr/lib/python3.8/ssl.py", line 1099, in read
    return self._sslobj.read(len, buffer)
ConnectionResetError: [Errno 104] Connection reset by peer

During handling of the above exception, another exception occurred:

Traceback (most recent call last):
  File "scraper.py", line 85, in <module>
    shutil.copyfileobj(res.raw, f)
  File "/usr/lib/python3.8/shutil.py", line 205, in copyfileobj
    buf = fsrc_read(length)
  File "/usr/lib/python3/dist-packages/urllib3/response.py", line 529, in read
    raise IncompleteRead(self._fp_bytes_read, self.length_remaining)
  File "/usr/lib/python3.8/contextlib.py", line 131, in __exit__
    self.gen.throw(type, value, traceback)
  File "/usr/lib/python3/dist-packages/urllib3/response.py", line 443, in _error_catcher
    raise ProtocolError("Connection broken: %r" % e, e)
urllib3.exceptions.ProtocolError: ("Connection broken: ConnectionResetError(104, 'Connection reset by peer')", ConnectionResetError(104, 'Connection reset by peer'))
